>     conn.query(q)
>   File "/opt/venv/lib/python3.7/site-packages/pymysql/connections.py", line 517, in query
>     self._affected_rows = self._read_query_result(unbuffered=unbuffered)
>   File "/opt/venv/lib/python3.7/site-packages/pymysql/connections.py", line 732, in _read_query_result
>     result.read()
>   File "/opt/venv/lib/python3.7/site-packages/pymysql/connections.py", line 1075, in read
>     first_packet = self.connection._read_packet()
>   File "/opt/venv/lib/python3.7/site-packages/pymysql/connections.py", line 684, in _read_packet
>     packet.check_error()
>   File "/opt/venv/lib/python3.7/site-packages/pymysql/protocol.py", line 220, in check_error
>     err.raise_mysql_exception(self._data)
>   File "/opt/venv/lib/python3.7/site-packages/pymysql/err.py", line 109, in raise_mysql_exception
>     raise errorclass(errno, errval)
> django.db.utils.OperationalError: (1142, "CREATE command denied to user 'crashmonitorbotfire_chinaqa_rw0'@'10.199.5
8.186' for
sh: e: command not found
sh-4.2$ table 'django_migrations'")
>
> During handling of the above exception, another exception occurred:
>
> Traceback (most recent call last):
>   File "manage.py", line 22, in <module>
>     main()
>   File "manage.py", line 18, in main
>     execute_from_command_line(sys.argv)
>   File "/opt/venv/lib/python3.7/site-packages/django/core/management/__init__.py", line 419, in execute_from_comman
d_line
>     utility.execute()
>   File "/opt/venv/lib/python3.7/site-packages/django/core/management/__init__.py", line 413, in execute
>     self.fetch_command(subcommand).run_from_argv(self.argv)
>   File "/opt/venv/lib/python3.7/site-packages/django/core/management/base.py", line 354, in run_from_argv
>     self.execute(*args, **cmd_options)
>   File "/opt/venv/lib/python3.7/site-packages/django/core/management/base.py", line 398, in execute
>     output = self.handle(*args, **options)
>   File "/opt/venv/lib/python3.7/site-packages/django/core/management/base.py", line 89, in wrapped
>     res = handle_func(*args, **kwargs)
>   File "/opt/venv/lib/python3.7/site-packages/django/core/management/commands/migrate.py", line 246, in handle
>     fake_initial=fake_initial,
>   File "/opt/venv/lib/python3.7/site-packages/django/db/migrations/executor.py", line 91, in migrate
>     self.recorder.ensure_schema()
>   File "/opt/venv/lib/python3.7/site-packages/django/db/migrations/recorder.py", line 70, in ensure_schema
>     raise MigrationSchemaMissing("Unable to create the django_migrations table (%s)" % exc)
sh: syntax error near unexpected token `('
sh-4.2$ django.db.migrations.exceptions.MigrationSchemaMissing: Unable to create the django_migrations table ((1142,
"CREATE command d
sh: syntax error near unexpected token `('
sh-4.2$ enied to user 'crashmonitorbotfire_chinaqa_rw0'@'10.199.58.186' for table 'django_migrations'"))
> sh-4.2$
> sh-4.2$
> sh-4.2$ cat /var/run/secrets/booking.com/
> db.json            identity.1.key     identity.2.key     issuer.public.key
> sh-4.2$ cat /var/run/secrets/booking.com/
> db.json            identity.1.key     identity.2.key     issuer.public.key
> sh-4.2$ cat /var/run/secrets/booking.com/db.json
> {"database":{"android":{"ro":{"database":"android","driver":"mysql","password":"sZRPbhx7r9PQPjeX","rdbprod_roster":
"androiddb-
sh: enied: command not found
sh-4.2$ rdbprod","roster":"androiddb-dqs_set","username":"crashmonitorbotfire_android_ro0"}},"chinaqa":{"ro":{"databa
se":"chinaqa","dr
sh: rdbprod,roster:androiddb-dqs_set,username:crashmonitorbotfire_android_ro0}},chinaqa:{ro:{database:chinaqa,dr: com
mand not found
sh-4.2$ iver":"mysql","password":"YS1r2ubBhNifUh6a","rdbprod_roster":"inttooldb-rdbprod","roster":"inttooldb-dqs_set"
,"username":"cras
sh: iver:mysql,password:YS1r2ubBhNifUh6a,rdbprod_roster:inttooldb-rdbprod,roster:inttooldb-dqs_set,username:cras: com
mand not found
sh-4.2$ hmonitorbotfire_chinaqa_ro0"},"rw":{"database":"chinaqa","driver":"mysql","host":"dev-inttoolmdb-vip.lhr4.dqs
.booking.com","pa
sh: hmonitorbotfire_chinaqa_ro0},rw:{database:chinaqa,driver:mysql,host:dev-inttoolmdb-vip.lhr4.dqs.booking.com,pa: c
ommand not found
sh-4.2$ ssword":"Ugzdq7E3PDzJ1wBp","username":"crashmonitorbotfire_chinaqa_rw0"}}}}sh-4.2$
> sh-4.2$
> sh-4.2$ python -m json.tool /var/run/secrets/booking.com/db.json
> {
>     "database": {
>         "android": {
>             "ro": {
>                 "database": "android",
>                 "driver": "mysql",
>                 "password": "sZRPbhx7r9PQPjeX",
>                 "rdbprod_roster": "androiddb-rdbprod",
>                 "roster": "androiddb-dqs_set",
>                 "username": "crashmonitorbotfire_android_ro0"
>             }
>         },
>         "chinaqa": {
>             "ro": {
>                 "database": "chinaqa",
>                 "driver": "mysql",
>                 "password": "YS1r2ubBhNifUh6a",
>                 "rdbprod_roster": "inttooldb-rdbprod",
>                 "roster": "inttooldb-dqs_set",
>                 "username": "crashmonitorbotfire_chinaqa_ro0"
>             },
>             "rw": {
>                 "database": "chinaqa",
>                 "driver": "mysql",
>                 "host": "dev-inttoolmdb-vip.lhr4.dqs.booking.com",
>                 "password": "Ugzdq7E3PDzJ1wBp",
>                 "username": "crashmonitorbotfire_chinaqa_rw0"
>             }
>         }
>     }
> }
> sh-4.2$ which mysql
> which: no mysql in (/opt/venv/bin:/usr/local/sbin:/usr/local/bin:/usr/sbin:/usr/bin:/sbin:/bin)
> sh-4.2$
> sh-4.2$
> sh-4.2$
> Display all 774 possibilities? (y or n)
> sh-4.2$
> sh-4.2$
>
>
>
> ^C
sh-4.2$
sh-4.2$
sh-4.2$
sh-4.2$ ssword":"Ugzdq7E3PDzJ1wBp","username":"crashmonitorbotfire_chinaqa_rw0"}}}}sh-4.2$
sh-4.2$ hmonitorbotfire_chinaqa_ro0"},"rw":{"database":"chinaqa","driver":"mysql","host":"dev-inttoolmdb-vip.lhr4.dqs
.bookinge 'django_migrations'")
        pymysql.err.OperationalError: (1142, "CREATE command denied to user 'crashmonitorbotfire_chinaqa_rw0'@'10.199
.58.186'
sh-4.2$
sh-4.2$ history | grep migrate
    9  python manage.py migrate
  File "/opt/venv/lib/python3.7/site-packages/django/core/management/commands/migrate.py", line 246, in handle
  File "/opt/venv/lib/python3.7/site-packages/django/db/migrations/executor.py", line 91, in migrate
   55  history | grep migrate
sh-4.2$
sh-4.2$ python manage.py migrat
Unknown command: 'migrat'. Did you mean migrate?
Type 'manage.py help' for usage.
sh-4.2$ python manage.py migrate
Operations to perform:
  Apply all migrations: admin, auth, contenttypes, issue_import, sessions
Running migrations:
Traceback (most recent call last):
  File "/opt/venv/lib/python3.7/site-packages/django/db/backends/utils.py", line 82, in _execute
    return self.cursor.execute(sql)
  File "/opt/venv/lib/python3.7/site-packages/django/db/backends/mysql/base.py", line 73, in execute
    return self.cursor.execute(query, args)
  File "/opt/venv/lib/python3.7/site-packages/pymysql/cursors.py", line 170, in execute
    result = self._query(query)
  File "/opt/venv/lib/python3.7/site-packages/pymysql/cursors.py", line 328, in _query
    conn.query(q)
  File "/opt/venv/lib/python3.7/site-packages/pymysql/connections.py", line 517, in query
    self._affected_rows = self._read_query_result(unbuffered=unbuffered)
  File "/opt/venv/lib/python3.7/site-packages/pymysql/connections.py", line 732, in _read_query_result
    result.read()
  File "/opt/venv/lib/python3.7/site-packages/pymysql/connections.py", line 1075, in read
    first_packet = self.connection._read_packet()
  File "/opt/venv/lib/python3.7/site-packages/pymysql/connections.py", line 684, in _read_packet
    packet.check_error()
  File "/opt/venv/lib/python3.7/site-packages/pymysql/protocol.py", line 220, in check_error
    err.raise_mysql_exception(self._data)
  File "/opt/venv/lib/python3.7/site-packages/pymysql/err.py", line 109, in raise_mysql_exception
    raise errorclass(errno, errval)
pymysql.err.OperationalError: (1142, "CREATE command denied to user 'crashmonitorbotfire_chinaqa_rw0'@'10.199.58.186'
 for table 'django_migrations'")

The above exception was the direct cause of the following exception:

Traceback (most recent call last):
  File "/opt/venv/lib/python3.7/site-packages/django/db/migrations/recorder.py", line 68, in ensure_schema
    editor.create_model(self.Migration)
  File "/opt/venv/lib/python3.7/site-packages/django/db/backends/base/schema.py", line 331, in create_model
    self.execute(sql, params or None)
  File "/opt/venv/lib/python3.7/site-packages/django/db/backends/base/schema.py", line 145, in execute
    cursor.execute(sql, params)
  File "/opt/venv/lib/python3.7/site-packages/django/db/backends/utils.py", line 98, in execute
    return super().execute(sql, params)
  File "/opt/venv/lib/python3.7/site-packages/django/db/backends/utils.py", line 66, in execute
    return self._execute_with_wrappers(sql, params, many=False, executor=self._execute)
  File "/opt/venv/lib/python3.7/site-packages/django/db/backends/utils.py", line 75, in _execute_with_wrappers
    return executor(sql, params, many, context)
  File "/opt/venv/lib/python3.7/site-packages/django/db/backends/utils.py", line 84, in _execute
    return self.cursor.execute(sql, params)
  File "/opt/venv/lib/python3.7/site-packages/django/db/utils.py", line 90, in __exit__
    raise dj_exc_value.with_traceback(traceback) from exc_value
  File "/opt/venv/lib/python3.7/site-packages/django/db/backends/utils.py", line 82, in _execute
    return self.cursor.execute(sql)
  File "/opt/venv/lib/python3.7/site-packages/django/db/backends/mysql/base.py", line 73, in execute
    return self.cursor.execute(query, args)
  File "/opt/venv/lib/python3.7/site-packages/pymysql/cursors.py", line 170, in execute
    result = self._query(query)
  File "/opt/venv/lib/python3.7/site-packages/pymysql/cursors.py", line 328, in _query
    conn.query(q)
  File "/opt/venv/lib/python3.7/site-packages/pymysql/connections.py", line 517, in query
    self._affected_rows = self._read_query_result(unbuffered=unbuffered)
  File "/opt/venv/lib/python3.7/site-packages/pymysql/connections.py", line 732, in _read_query_result
    result.read()
  File "/opt/venv/lib/python3.7/site-packages/pymysql/connections.py", line 1075, in read
    first_packet = self.connection._read_packet()
  File "/opt/venv/lib/python3.7/site-packages/pymysql/connections.py", line 684, in _read_packet
    packet.check_error()
  File "/opt/venv/lib/python3.7/site-packages/pymysql/protocol.py", line 220, in check_error
    err.raise_mysql_exception(self._data)
  File "/opt/venv/lib/python3.7/site-packages/pymysql/err.py", line 109, in raise_mysql_exception
    raise errorclass(errno, errval)
django.db.utils.OperationalError: (1142, "CREATE command denied to user 'crashmonitorbotfire_chinaqa_rw0'@'10.199.58.
186' for table 'django_migrations'")

During handling of the above exception, another exception occurred:

Traceback (most recent call last):
  File "manage.py", line 22, in <module>
    main()
  File "manage.py", line 18, in main
    execute_from_command_line(sys.argv)
  File "/opt/venv/lib/python3.7/site-packages/django/core/management/__init__.py", line 419, in execute_from_command_
line
    utility.execute()
  File "/opt/venv/lib/python3.7/site-packages/django/core/management/__init__.py", line 413, in execute
    self.fetch_command(subcommand).run_from_argv(self.argv)
  File "/opt/venv/lib/python3.7/site-packages/django/core/management/base.py", line 354, in run_from_argv
    self.execute(*args, **cmd_options)
  File "/opt/venv/lib/python3.7/site-packages/django/core/management/base.py", line 398, in execute
    output = self.handle(*args, **options)
  File "/opt/venv/lib/python3.7/site-packages/django/core/management/base.py", line 89, in wrapped
    res = handle_func(*args, **kwargs)
  File "/opt/venv/lib/python3.7/site-packages/django/core/management/commands/migrate.py", line 246, in handle
    fake_initial=fake_initial,
  File "/opt/venv/lib/python3.7/site-packages/django/db/migrations/executor.py", line 91, in migrate
    self.recorder.ensure_schema()
  File "/opt/venv/lib/python3.7/site-packages/django/db/migrations/recorder.py", line 70, in ensure_schema
    raise MigrationSchemaMissing("Unable to create the django_migrations table (%s)" % exc)
django.db.migrations.exceptions.MigrationSchemaMissing: Unable to create the django_migrations table ((1142, "CREATE
command denied to user 'crashmonitorbotfire_chinaqa_rw0'@'10.199.58.186' for table 'django_migrations'"))
sh-4.2$
