  File "/usr/local/opt/python@3.7/Frameworks/Python.framework/Versions/3.7/lib/python3.7/site-packages/sqlalchemy/pool/base.py", line 362, in __init__
    self.__connect(first_connect_check=True)
  File "/usr/local/opt/python@3.7/Frameworks/Python.framework/Versions/3.7/lib/python3.7/site-packages/sqlalchemy/pool/base.py", line 605, in __connect
    pool.logger.debug("Error on connect(): %s", e)
  File "/usr/local/opt/python@3.7/Frameworks/Python.framework/Versions/3.7/lib/python3.7/site-packages/sqlalchemy/util/langhelpers.py", line 72, in __exit__
    with_traceback=exc_tb,
  File "/usr/local/opt/python@3.7/Frameworks/Python.framework/Versions/3.7/lib/python3.7/site-packages/sqlalchemy/util/compat.py", line 211, in raise_
    raise exception
  File "/usr/local/opt/python@3.7/Frameworks/Python.framework/Versions/3.7/lib/python3.7/site-packages/sqlalchemy/pool/base.py", line 599, in __connect
    connection = pool._invoke_creator(self)
  File "/usr/local/opt/python@3.7/Frameworks/Python.framework/Versions/3.7/lib/python3.7/site-packages/sqlalchemy/engine/create.py", line 578, in connect
    return dialect.connect(*cargs, **cparams)
  File "/usr/local/opt/python@3.7/Frameworks/Python.framework/Versions/3.7/lib/python3.7/site-packages/sqlalchemy/engine/default.py", line 583, in connect
    return self.dbapi.connect(*cargs, **cparams)
  File "/usr/local/opt/python@3.7/Frameworks/Python.framework/Versions/3.7/lib/python3.7/site-packages/mysql/connector/__init__.py", line 273, in connect
    return MySQLConnection(*args, **kwargs)
  File "/usr/local/opt/python@3.7/Frameworks/Python.framework/Versions/3.7/lib/python3.7/site-packages/mysql/connector/connection.py", line 107, in __init__
    self.connect(**kwargs)
  File "/usr/local/opt/python@3.7/Frameworks/Python.framework/Versions/3.7/lib/python3.7/site-packages/mysql/connector/abstracts.py", line 1003, in connect
    self._open_connection()
  File "/usr/local/opt/python@3.7/Frameworks/Python.framework/Versions/3.7/lib/python3.7/site-packages/mysql/connector/connection.py", line 350, in _open_connection
    self._socket.open_connection()
  File "/usr/local/opt/python@3.7/Frameworks/Python.framework/Versions/3.7/lib/python3.7/site-packages/mysql/connector/network.py", line 566, in open_connection
    errno=2003, values=(self.get_address(), _strioerror(err)))
sqlalchemy.exc.InterfaceError: (mysql.connector.errors.InterfaceError) 2003: Can't connect to MySQL server on '%-.100s:%u' (%s) (Warning: %u format: a number is required,
not str)
(Background on this error at: http://sqlalche.me/e/14/rvf5)
>>>
>>>
>>> verticals_ro = cm.get_connection('verticals', 'ro')
Traceback (most recent call last):
  File "<stdin>", line 1, in <module>
  File "/usr/local/opt/python@3.7/Frameworks/Python.framework/Versions/3.7/lib/python3.7/site-packages/bkng/infra/db/dbconnectionmanager.py", line 90, in get_connection
    host_ = self.roster_manager.next_roster_item(f"{self._roster_base_path}/{conn_params['roster']}")
  File "/usr/local/opt/python@3.7/Frameworks/Python.framework/Versions/3.7/lib/python3.7/site-packages/bkng/infra/roster/manager.py", line 417, in next_roster_item
    properties = RosterManager.add_roster_file(roster_file)
  File "/usr/local/opt/python@3.7/Frameworks/Python.framework/Versions/3.7/lib/python3.7/site-packages/bkng/infra/roster/manager.py", line 162, in add_roster_file
    roster_file, panic_file
  File "/usr/local/opt/python@3.7/Frameworks/Python.framework/Versions/3.7/lib/python3.7/site-packages/bkng/infra/roster/manager.py", line 104, in __construct_cache_key_an
d_get_file_stats_for_roster
    raise FailedToReadRosterException("ROSTER ERROR: Failed to read roster - {}".format(roster_file))
bkng.infra.roster.manager.FailedToReadRosterException: ROSTER ERROR: Failed to read roster - /etc/bookings/pool_roster/experiencesdb-dqs_set
>>>
>>>
>>> verticals_ro = cm.get_connection('verticals', 'ro')
>>>
>>> c = verticals_ro.execute("SELECT @@global.hostname")
Traceback (most recent call last):
  File "/usr/local/opt/python@3.7/Frameworks/Python.framework/Versions/3.7/lib/python3.7/site-packages/mysql/connector/network.py", line 550, in open_connection
    socket.SOL_TCP)
  File "/usr/local/opt/python@3.7/Frameworks/Python.framework/Versions/3.7/lib/python3.7/socket.py", line 752, in getaddrinfo
    for res in _socket.getaddrinfo(host, port, family, type, proto, flags):
socket.gaierror: [Errno 8] nodename nor servname provided, or not known

During handling of the above exception, another exception occurred:

Traceback (most recent call last):
  File "/usr/local/opt/python@3.7/Frameworks/Python.framework/Versions/3.7/lib/python3.7/site-packages/sqlalchemy/engine/base.py", line 3141, in _wrap_pool_connect
    return fn()
  File "/usr/local/opt/python@3.7/Frameworks/Python.framework/Versions/3.7/lib/python3.7/site-packages/sqlalchemy/pool/base.py", line 301, in connect
    return _ConnectionFairy._checkout(self)
  File "/usr/local/opt/python@3.7/Frameworks/Python.framework/Versions/3.7/lib/python3.7/site-packages/sqlalchemy/pool/base.py", line 755, in _checkout
    fairy = _ConnectionRecord.checkout(pool)
  File "/usr/local/opt/python@3.7/Frameworks/Python.framework/Versions/3.7/lib/python3.7/site-packages/sqlalchemy/pool/base.py", line 419, in checkout
    rec = pool._do_get()
  File "/usr/local/opt/python@3.7/Frameworks/Python.framework/Versions/3.7/lib/python3.7/site-packages/sqlalchemy/pool/impl.py", line 145, in _do_get
    self._dec_overflow()
  File "/usr/local/opt/python@3.7/Frameworks/Python.framework/Versions/3.7/lib/python3.7/site-packages/sqlalchemy/util/langhelpers.py", line 72, in __exit__
    with_traceback=exc_tb,
  File "/usr/local/opt/python@3.7/Frameworks/Python.framework/Versions/3.7/lib/python3.7/site-packages/sqlalchemy/util/compat.py", line 211, in raise_
    raise exception
  File "/usr/local/opt/python@3.7/Frameworks/Python.framework/Versions/3.7/lib/python3.7/site-packages/sqlalchemy/pool/impl.py", line 142, in _do_get
    return self._create_connection()
  File "/usr/local/opt/python@3.7/Frameworks/Python.framework/Versions/3.7/lib/python3.7/site-packages/sqlalchemy/pool/base.py", line 247, in _create_connection
    return _ConnectionRecord(self)
  File "/usr/local/opt/python@3.7/Frameworks/Python.framework/Versions/3.7/lib/python3.7/site-packages/sqlalchemy/pool/base.py", line 362, in __init__
    self.__connect(first_connect_check=True)
  File "/usr/local/opt/python@3.7/Frameworks/Python.framework/Versions/3.7/lib/python3.7/site-packages/sqlalchemy/pool/base.py", line 605, in __connect
    pool.logger.debug("Error on connect(): %s", e)
  File "/usr/local/opt/python@3.7/Frameworks/Python.framework/Versions/3.7/lib/python3.7/site-packages/sqlalchemy/util/langhelpers.py", line 72, in __exit__
    with_traceback=exc_tb,
  File "/usr/local/opt/python@3.7/Frameworks/Python.framework/Versions/3.7/lib/python3.7/site-packages/sqlalchemy/util/compat.py", line 211, in raise_
    raise exception
  File "/usr/local/opt/python@3.7/Frameworks/Python.framework/Versions/3.7/lib/python3.7/site-packages/sqlalchemy/pool/base.py", line 599, in __connect
    connection = pool._invoke_creator(self)
  File "/usr/local/opt/python@3.7/Frameworks/Python.framework/Versions/3.7/lib/python3.7/site-packages/sqlalchemy/engine/create.py", line 578, in connect
    return dialect.connect(*cargs, **cparams)
  File "/usr/local/opt/python@3.7/Frameworks/Python.framework/Versions/3.7/lib/python3.7/site-packages/sqlalchemy/engine/default.py", line 583, in connect
    return self.dbapi.connect(*cargs, **cparams)
  File "/usr/local/opt/python@3.7/Frameworks/Python.framework/Versions/3.7/lib/python3.7/site-packages/mysql/connector/__init__.py", line 273, in connect
    return MySQLConnection(*args, **kwargs)
  File "/usr/local/opt/python@3.7/Frameworks/Python.framework/Versions/3.7/lib/python3.7/site-packages/mysql/connector/connection.py", line 107, in __init__
    self.connect(**kwargs)
  File "/usr/local/opt/python@3.7/Frameworks/Python.framework/Versions/3.7/lib/python3.7/site-packages/mysql/connector/abstracts.py", line 1003, in connect
    self._open_connection()
  File "/usr/local/opt/python@3.7/Frameworks/Python.framework/Versions/3.7/lib/python3.7/site-packages/mysql/connector/connection.py", line 350, in _open_connection
    self._socket.open_connection()
  File "/usr/local/opt/python@3.7/Frameworks/Python.framework/Versions/3.7/lib/python3.7/site-packages/mysql/connector/network.py", line 566, in open_connection
    errno=2003, values=(self.get_address(), _strioerror(err)))
mysql.connector.errors.InterfaceError: 2003: Can't connect to MySQL server on '%-.100s:%u' (%s) (Warning: %u format: a number is required, not str)

The above exception was the direct cause of the following exception:

Traceback (most recent call last):
  File "<stdin>", line 1, in <module>
  File "<string>", line 2, in execute
  File "/usr/local/opt/python@3.7/Frameworks/Python.framework/Versions/3.7/lib/python3.7/site-packages/sqlalchemy/util/deprecations.py", line 390, in warned
    return fn(*args, **kwargs)
  File "/usr/local/opt/python@3.7/Frameworks/Python.framework/Versions/3.7/lib/python3.7/site-packages/sqlalchemy/engine/base.py", line 3036, in execute
    connection = self.connect(close_with_result=True)
  File "/usr/local/opt/python@3.7/Frameworks/Python.framework/Versions/3.7/lib/python3.7/site-packages/sqlalchemy/engine/base.py", line 3095, in connect
    return self._connection_cls(self, close_with_result=close_with_result)
  File "/usr/local/opt/python@3.7/Frameworks/Python.framework/Versions/3.7/lib/python3.7/site-packages/sqlalchemy/engine/base.py", line 91, in __init__
    else engine.raw_connection()
  File "/usr/local/opt/python@3.7/Frameworks/Python.framework/Versions/3.7/lib/python3.7/site-packages/sqlalchemy/engine/base.py", line 3174, in raw_connection
    return self._wrap_pool_connect(self.pool.connect, _connection)
  File "/usr/local/opt/python@3.7/Frameworks/Python.framework/Versions/3.7/lib/python3.7/site-packages/sqlalchemy/engine/base.py", line 3145, in _wrap_pool_connect
    e, dialect, self
  File "/usr/local/opt/python@3.7/Frameworks/Python.framework/Versions/3.7/lib/python3.7/site-packages/sqlalchemy/engine/base.py", line 2004, in _handle_dbapi_exception_no
connection
    sqlalchemy_exception, with_traceback=exc_info[2], from_=e
  File "/usr/local/opt/python@3.7/Frameworks/Python.framework/Versions/3.7/lib/python3.7/site-packages/sqlalchemy/util/compat.py", line 211, in raise_
    raise exception
  File "/usr/local/opt/python@3.7/Frameworks/Python.framework/Versions/3.7/lib/python3.7/site-packages/sqlalchemy/engine/base.py", line 3141, in _wrap_pool_connect
    return fn()
  File "/usr/local/opt/python@3.7/Frameworks/Python.framework/Versions/3.7/lib/python3.7/site-packages/sqlalchemy/pool/base.py", line 301, in connect
    return _ConnectionFairy._checkout(self)
  File "/usr/local/opt/python@3.7/Frameworks/Python.framework/Versions/3.7/lib/python3.7/site-packages/sqlalchemy/pool/base.py", line 755, in _checkout
    fairy = _ConnectionRecord.checkout(pool)
  File "/usr/local/opt/python@3.7/Frameworks/Python.framework/Versions/3.7/lib/python3.7/site-packages/sqlalchemy/pool/base.py", line 419, in checkout
    rec = pool._do_get()
  File "/usr/local/opt/python@3.7/Frameworks/Python.framework/Versions/3.7/lib/python3.7/site-packages/sqlalchemy/pool/impl.py", line 145, in _do_get
    self._dec_overflow()
  File "/usr/local/opt/python@3.7/Frameworks/Python.framework/Versions/3.7/lib/python3.7/site-packages/sqlalchemy/util/langhelpers.py", line 72, in __exit__
    with_traceback=exc_tb,
  File "/usr/local/opt/python@3.7/Frameworks/Python.framework/Versions/3.7/lib/python3.7/site-packages/sqlalchemy/util/compat.py", line 211, in raise_
    raise exception
  File "/usr/local/opt/python@3.7/Frameworks/Python.framework/Versions/3.7/lib/python3.7/site-packages/sqlalchemy/pool/impl.py", line 142, in _do_get
    return self._create_connection()
  File "/usr/local/opt/python@3.7/Frameworks/Python.framework/Versions/3.7/lib/python3.7/site-packages/sqlalchemy/pool/base.py", line 247, in _create_connection
    return _ConnectionRecord(self)
  File "/usr/local/opt/python@3.7/Frameworks/Python.framework/Versions/3.7/lib/python3.7/site-packages/sqlalchemy/pool/base.py", line 362, in __init__
    self.__connect(first_connect_check=True)
  File "/usr/local/opt/python@3.7/Frameworks/Python.framework/Versions/3.7/lib/python3.7/site-packages/sqlalchemy/pool/base.py", line 605, in __connect
    pool.logger.debug("Error on connect(): %s", e)
  File "/usr/local/opt/python@3.7/Frameworks/Python.framework/Versions/3.7/lib/python3.7/site-packages/sqlalchemy/util/langhelpers.py", line 72, in __exit__
    with_traceback=exc_tb,
  File "/usr/local/opt/python@3.7/Frameworks/Python.framework/Versions/3.7/lib/python3.7/site-packages/sqlalchemy/util/compat.py", line 211, in raise_
    raise exception
  File "/usr/local/opt/python@3.7/Frameworks/Python.framework/Versions/3.7/lib/python3.7/site-packages/sqlalchemy/pool/base.py", line 599, in __connect
    connection = pool._invoke_creator(self)
  File "/usr/local/opt/python@3.7/Frameworks/Python.framework/Versions/3.7/lib/python3.7/site-packages/sqlalchemy/engine/create.py", line 578, in connect
    return dialect.connect(*cargs, **cparams)
  File "/usr/local/opt/python@3.7/Frameworks/Python.framework/Versions/3.7/lib/python3.7/site-packages/sqlalchemy/engine/default.py", line 583, in connect
    return self.dbapi.connect(*cargs, **cparams)
  File "/usr/local/opt/python@3.7/Frameworks/Python.framework/Versions/3.7/lib/python3.7/site-packages/mysql/connector/__init__.py", line 273, in connect
    return MySQLConnection(*args, **kwargs)
  File "/usr/local/opt/python@3.7/Frameworks/Python.framework/Versions/3.7/lib/python3.7/site-packages/mysql/connector/connection.py", line 107, in __init__
    self.connect(**kwargs)
  File "/usr/local/opt/python@3.7/Frameworks/Python.framework/Versions/3.7/lib/python3.7/site-packages/mysql/connector/abstracts.py", line 1003, in connect
    self._open_connection()
  File "/usr/local/opt/python@3.7/Frameworks/Python.framework/Versions/3.7/lib/python3.7/site-packages/mysql/connector/connection.py", line 350, in _open_connection
    self._socket.open_connection()
  File "/usr/local/opt/python@3.7/Frameworks/Python.framework/Versions/3.7/lib/python3.7/site-packages/mysql/connector/network.py", line 566, in open_connection
    errno=2003, values=(self.get_address(), _strioerror(err)))
sqlalchemy.exc.InterfaceError: (mysql.connector.errors.InterfaceError) 2003: Can't connect to MySQL server on '%-.100s:%u' (%s) (Warning: %u format: a number is required,
not str)
(Background on this error at: http://sqlalche.me/e/14/rvf5)
>>>
